If MySQL gives an error about sockets:

The error message you're encountering indicates that SQLAlchemy is unable to connect to the MySQL server via the default socket /var/run/mysqld/mysqld.sock. This could be due to a number of issues such as MySQL not running, an incorrect socket path, or a misconfigured MySQL server.

To fix:
-----

SOLUTION 1:
-------------

Remove "localhost" and pass 127.0.01

engine = create_engine(f"mysql+mysqldb://<user>:<password>@127.0.0.1/humans")

SOLUTION 2:
-------------

Check if MySQL is up and running

Find the type of socket your MySQL is currently using: sudo grep 'socket' /etc/mysql/my.cnf

Pass that socket as an argument

To MySQLd:
------------

connection = MySQLdb.connect(
    host="localhost",
    user="your_username",
    passwd="your_password",
    db="your_database",
    unix_socket="/path/to/mysql.sock"
)

Example
======

connection = MySQLdb.connect(
    host="localhost",
    port=3306,
    unix_socket="/var/run/mysqld/mysqlx.sock",
    user=argv[1],
    passwd=argv[2],
    db=argv[3],
)

To SQLAlchemy:
----------------

engine = create_engine(
f"mysql+mysqldb://<user>:<password>@localhost/<database>?unix_socket=/path/to/your/mysql.sock"
)
Base = declarative_base()

Example:
=======

engine = create_engine(
    f"mysql+mysqldb://<user>:<password>@127.0.0.1/humans"
)
Base = declarative_base()

OR

engine = create_engine(
    f"mysql+mysqldb://<user>:<password>@localhost/<database>?unix_socket=/var/run/mysqld/mysqlx.sock"
)
Base = declarative_base()




Traceback (most recent call last):
  File "/home/tafara/.venv/lib/python3.12/site-packages/sqlalchemy/engine/base.py", line 145, in __init__
    self._dbapi_connection = engine.raw_connection()
                             ^^^^^^^^^^^^^^^^^^^^^^^
  File "/home/tafara/.venv/lib/python3.12/site-packages/sqlalchemy/engine/base.py", line 3293, in raw_connection
    return self.pool.connect()
           ^^^^^^^^^^^^^^^^^^^
  File "/home/tafara/.venv/lib/python3.12/site-packages/sqlalchemy/pool/base.py", line 452, in connect
    return _ConnectionFairy._checkout(self)
           ^^^^^^^^^^^^^^^^^^^^^^^^^^^^^^^^
  File "/home/tafara/.venv/lib/python3.12/site-packages/sqlalchemy/pool/base.py", line 1269, in _checkout
    fairy = _ConnectionRecord.checkout(pool)
            ^^^^^^^^^^^^^^^^^^^^^^^^^^^^^^^^
  File "/home/tafara/.venv/lib/python3.12/site-packages/sqlalchemy/pool/base.py", line 716, in checkout
    rec = pool._do_get()
          ^^^^^^^^^^^^^^
  File "/home/tafara/.venv/lib/python3.12/site-packages/sqlalchemy/pool/impl.py", line 169, in _do_get
    with util.safe_reraise():
  File "/home/tafara/.venv/lib/python3.12/site-packages/sqlalchemy/util/langhelpers.py", line 146, in __exit__
    raise exc_value.with_traceback(exc_tb)
  File "/home/tafara/.venv/lib/python3.12/site-packages/sqlalchemy/pool/impl.py", line 167, in _do_get
    return self._create_connection()
           ^^^^^^^^^^^^^^^^^^^^^^^^^
  File "/home/tafara/.venv/lib/python3.12/site-packages/sqlalchemy/pool/base.py", line 393, in _create_connection
    return _ConnectionRecord(self)
           ^^^^^^^^^^^^^^^^^^^^^^^
  File "/home/tafara/.venv/lib/python3.12/site-packages/sqlalchemy/pool/base.py", line 678, in __init__
    self.__connect()
  File "/home/tafara/.venv/lib/python3.12/site-packages/sqlalchemy/pool/base.py", line 902, in __connect
    with util.safe_reraise():
  File "/home/tafara/.venv/lib/python3.12/site-packages/sqlalchemy/util/langhelpers.py", line 146, in __exit__
    raise exc_value.with_traceback(exc_tb)
  File "/home/tafara/.venv/lib/python3.12/site-packages/sqlalchemy/pool/base.py", line 898, in __connect
    self.dbapi_connection = connection = pool._invoke_creator(self)
                                         ^^^^^^^^^^^^^^^^^^^^^^^^^^
  File "/home/tafara/.venv/lib/python3.12/site-packages/sqlalchemy/engine/create.py", line 645, in connect
    return dialect.connect(*cargs, **cparams)
           ^^^^^^^^^^^^^^^^^^^^^^^^^^^^^^^^^^
  File "/home/tafara/.venv/lib/python3.12/site-packages/sqlalchemy/engine/default.py", line 616, in connect
    return self.loaded_dbapi.connect(*cargs, **cparams)
           ^^^^^^^^^^^^^^^^^^^^^^^^^^^^^^^^^^^^^^^^^^^^
  File "/home/tafara/.venv/lib/python3.12/site-packages/MySQLdb/__init__.py", line 121, in Connect
    return Connection(*args, **kwargs)
           ^^^^^^^^^^^^^^^^^^^^^^^^^^^
  File "/home/tafara/.venv/lib/python3.12/site-packages/MySQLdb/connections.py", line 195, in __init__
    super().__init__(*args, **kwargs2)
MySQLdb.OperationalError: (2002, "Can't connect to local MySQL server through socket '/var/run/mysqld/mysqld.sock' (2)")

The above exception was the direct cause of the following exception:

Traceback (most recent call last):
  File "/home/tafara/Documents/Code/Python/core/sql_alchemy/MySQL/./create_tables.py", line 17, in <module>
    with engine.connect() as connected:
         ^^^^^^^^^^^^^^^^
  File "/home/tafara/.venv/lib/python3.12/site-packages/sqlalchemy/engine/base.py", line 3269, in connect
    return self._connection_cls(self)
           ^^^^^^^^^^^^^^^^^^^^^^^^^^
  File "/home/tafara/.venv/lib/python3.12/site-packages/sqlalchemy/engine/base.py", line 147, in __init__
    Connection._handle_dbapi_exception_noconnection(
  File "/home/tafara/.venv/lib/python3.12/site-packages/sqlalchemy/engine/base.py", line 2431, in _handle_dbapi_exception_noconnection
    raise sqlalchemy_exception.with_traceback(exc_info[2]) from e
  File "/home/tafara/.venv/lib/python3.12/site-packages/sqlalchemy/engine/base.py", line 145, in __init__
    self._dbapi_connection = engine.raw_connection()
                             ^^^^^^^^^^^^^^^^^^^^^^^
  File "/home/tafara/.venv/lib/python3.12/site-packages/sqlalchemy/engine/base.py", line 3293, in raw_connection
    return self.pool.connect()
           ^^^^^^^^^^^^^^^^^^^
  File "/home/tafara/.venv/lib/python3.12/site-packages/sqlalchemy/pool/base.py", line 452, in connect
    return _ConnectionFairy._checkout(self)
           ^^^^^^^^^^^^^^^^^^^^^^^^^^^^^^^^
  File "/home/tafara/.venv/lib/python3.12/site-packages/sqlalchemy/pool/base.py", line 1269, in _checkout
    fairy = _ConnectionRecord.checkout(pool)
            ^^^^^^^^^^^^^^^^^^^^^^^^^^^^^^^^
  File "/home/tafara/.venv/lib/python3.12/site-packages/sqlalchemy/pool/base.py", line 716, in checkout
    rec = pool._do_get()
          ^^^^^^^^^^^^^^
  File "/home/tafara/.venv/lib/python3.12/site-packages/sqlalchemy/pool/impl.py", line 169, in _do_get
    with util.safe_reraise():
  File "/home/tafara/.venv/lib/python3.12/site-packages/sqlalchemy/util/langhelpers.py", line 146, in __exit__
    raise exc_value.with_traceback(exc_tb)
  File "/home/tafara/.venv/lib/python3.12/site-packages/sqlalchemy/pool/impl.py", line 167, in _do_get
    return self._create_connection()
           ^^^^^^^^^^^^^^^^^^^^^^^^^
  File "/home/tafara/.venv/lib/python3.12/site-packages/sqlalchemy/pool/base.py", line 393, in _create_connection
    return _ConnectionRecord(self)
           ^^^^^^^^^^^^^^^^^^^^^^^
  File "/home/tafara/.venv/lib/python3.12/site-packages/sqlalchemy/pool/base.py", line 678, in __init__
    self.__connect()
  File "/home/tafara/.venv/lib/python3.12/site-packages/sqlalchemy/pool/base.py", line 902, in __connect
    with util.safe_reraise():
  File "/home/tafara/.venv/lib/python3.12/site-packages/sqlalchemy/util/langhelpers.py", line 146, in __exit__
    raise exc_value.with_traceback(exc_tb)
  File "/home/tafara/.venv/lib/python3.12/site-packages/sqlalchemy/pool/base.py", line 898, in __connect
    self.dbapi_connection = connection = pool._invoke_creator(self)
                                         ^^^^^^^^^^^^^^^^^^^^^^^^^^
  File "/home/tafara/.venv/lib/python3.12/site-packages/sqlalchemy/engine/create.py", line 645, in connect
    return dialect.connect(*cargs, **cparams)
           ^^^^^^^^^^^^^^^^^^^^^^^^^^^^^^^^^^
  File "/home/tafara/.venv/lib/python3.12/site-packages/sqlalchemy/engine/default.py", line 616, in connect
    return self.loaded_dbapi.connect(*cargs, **cparams)
           ^^^^^^^^^^^^^^^^^^^^^^^^^^^^^^^^^^^^^^^^^^^^
  File "/home/tafara/.venv/lib/python3.12/site-packages/MySQLdb/__init__.py", line 121, in Connect
    return Connection(*args, **kwargs)
           ^^^^^^^^^^^^^^^^^^^^^^^^^^^
  File "/home/tafara/.venv/lib/python3.12/site-packages/MySQLdb/connections.py", line 195, in __init__
    super().__init__(*args, **kwargs2)
sqlalchemy.exc.OperationalError: (MySQLdb.OperationalError) (2002, "Can't connect to local MySQL server through socket '/var/run/mysqld/mysqld.sock' (2)")
(Background on this error at: https://sqlalche.me/e/20/e3q8)

--------------------------------------------------------------------------------
